<mujoco model="BHAM">
    <!--
    This file and the .stl mesh files referenced from it have been derived by Roboti LLC from the model of the Modular Prosthetic Limb developed by The Johns Hopkins University / Applied Physics Laboratory. The modifications are as follows: the original meshes have been replaced with their convex hulls; the original URDF model has been converted to the MJCF format and a number of MJCF-specific fields have been added.

    The Johns Hopkins University / Applied Physics Laboratory has given Roboti LLC permission to distribute the modified model under the following license:

    =========================

    (C) 2013 The Johns Hopkins University / Applied Physics Laboratory All Rights Reserved.

    Licensed under the Apache License, Version 2.0 (the "License"); you may not use this file except in compliance with the License. You may obtain a copy of the License at

    http://www.apache.org/licenses/LICENSE-2.0

    Unless required by applicable law or agreed to in writing, software distributed under the License is distributed on an "AS IS" BASIS, WITHOUT WARRANTIES OR CONDITIONS OF ANY KIND, either express or implied. See the License for the specific language governing permissions and limitations under the License.

    ========================

    The modifications made by Roboti LLC are also licensed under the Apache License version 2.0.
    -->
    
    <compiler angle="radian" meshdir="mesh/" texturedir="texture/" convexhull="true" coordinate="local"/>
    <option timestep="0.002" tolerance="1e-10" iterations="50" apirate="50" impratio="1.75" cone="elliptic"/>
    <size njmax="5000" nconmax="500" nstack="500000"/> 

    <default>
		<default class="BHAM"> 
			<geom material="MatMesh" contype="1" rgba="0.44 0.54 0.565 1" conaffinity="1" condim="4" solimp="0.9 0.95 0.001" solref="0.008 1.0" margin="0.001"/>
        	<joint limited="true" damping="0.2" armature=".01"/>
        	<site material="MatTouch" type="ellipsoid" group="3"/>
            <position kp="1" ctrllimited="true" forcelimited="true" forcerange="-1.25 1.25"/>
		</default>

        <default class="IMU">
	        <site material="MatIMU" type="box" group="4"/>
        </default>
        
        <default class="free">
            <joint type="free" damping="0" armature="0" limited="false"/>
        </default>     
    </default>

    <statistic extent="1" center="0 -0.2 0.2"/>

    <visual>
    	<global fovy="45"/>
        <quality shadowsize="10000"/>
    </visual>

    <asset>
		<mesh name="righthandbase" 		file="righthandbase.stl"/>
		<mesh name="palm1" 		file="palm1.stl"/>
		<mesh name="palm2" 		file="palm2.stl"/>
		<mesh name="palm3" 		file="palm3.stl"/>
		<mesh name="palm4" 		file="palm4.stl"/>
		<mesh name="palm5" 		file="palm5.stl"/>
		<mesh name="palm6" 		file="palm6.stl"/>
		<mesh name="palm7" 		file="palm7.stl"/>
		<mesh name="palm8" 		file="palm8.stl"/>
		<mesh name="palm9" 		file="palm9.stl"/>
		<mesh name="palm10" 		file="palm10.stl"/>
		<mesh name="palm11" 		file="palm11.stl"/>
		<mesh name="palm12" 		file="palm12.stl"/>
		<mesh name="palm13" 		file="palm13.stl"/>
		<mesh name="palm14" 		file="palm14.stl"/>
		<mesh name="palm15" 		file="palm15.stl"/>
		<mesh name="palm16" 		file="palm16.stl"/>
		<mesh name="palm17" 		file="palm17.stl"/>
		<mesh name="palm18" 		file="palm18.stl"/>
		<mesh name="palm19" 		file="palm19.stl"/>
		<mesh name="fore_basecover" 	file="fore_basecover.stl"/>
		<mesh name="fore_distalp" 		file="fore_distalp.stl"/>
		<mesh name="fore_middlep" 		file="fore_middlep.stl"/>
		<mesh name="fore_proximalp" 	file="fore_proximalp.stl"/>
		<mesh name="little_basecover" 	file="little_basecover.stl"/>
		<mesh name="little_distalp" 	file="little_distalp.stl"/>
		<mesh name="little_middlep" 	file="little_middlep.stl"/>
		<mesh name="little_proximalp" 	file="little_proximalp.stl"/>
		<mesh name="middle_basecover" 	file="middle_basecover.stl"/>
		<mesh name="middle_distalp" 	file="middle_distalp.stl"/>
		<mesh name="middle_middlep" 	file="middle_middlep.stl"/>
		<mesh name="middle_proximalp" 	file="middle_proximalp.stl"/>
		<mesh name="ring_basecover" 	file="ring_basecover.stl"/>
		<mesh name="ring_distalp" 		file="ring_distalp.stl"/>
		<mesh name="ring_middlep" 		file="ring_middlep.stl"/>
		<mesh name="ring_proximalp" 	file="ring_proximalp.stl"/>
		<mesh name="thumb_basecover" 	file="thumb_basecover.stl"/>
		<mesh name="thumb_distalp" 		file="thumb_distalp.stl"/>
		<mesh name="thumb_middlep" 		file="thumb_middlep.stl"/>
		<mesh name="thumb_proximalp" 	file="thumb_proximalp.stl"/>
        
		<texture type="skybox" builtin="gradient" rgb1=".4 .6 .8" rgb2="0 0 0" 
			width="100" height="100"/>
		<texture name="groundplane" type="2d" builtin="checker" rgb1=".2 .3 .4" rgb2=".1 .2 .3" 
            width="100" height="100"/>
		<texture name="skin" type="cube" file="skin.png"/>
		<texture name="marble2d" type="2d" file="marble.png"/>
		<texture name="marblecube" type="cube" file="marble.png"/>

		<material name="groundplane" texture="groundplane" texrepeat="10 10"/>
		<material name="table2d" texture="marble2d" reflectance="0.3" rgba=".8 .8 .8 1"/>
		<material name="tablecube" texture="marblecube" rgba=".8 .8 .8 1"/>
        <material name="MatTouch" rgba=".3 .9 .3 .3"/>
        <material name="MatIMU" rgba=".1 .1 .9 1"/>
        <material name="MatMesh" rgba=".6 .6 .6 1"/>
	</asset>

    <contact>  
		<exclude body1="palm" body2="thumb1"/>
        <exclude body1="palm" body2="fore1"/>
        <exclude body1="palm" body2="middle1"/>
        <exclude body1="palm" body2="ring1"/>
        <exclude body1="palm" body2="little1"/>
             
        <!--
        <exclude body1="mocap" body2="table"/>
        <exclude body1="palm" body2="table"/>
        <exclude body1="thumb0" body2="table"/>
        <exclude body1="thumb1" body2="table"/>
        <exclude body1="thumb2" body2="table"/>
        <exclude body1="thumb3" body2="table"/>
        <exclude body1="little0" body2="table"/>
        <exclude body1="little1" body2="table"/>
        <exclude body1="little2" body2="table"/>
        <exclude body1="little3" body2="table"/>
        <exclude body1="fore0" body2="table"/>
        <exclude body1="fore1" body2="table"/>
        <exclude body1="fore2" body2="table"/>
        <exclude body1="fore3" body2="table"/>
        <exclude body1="middle0" body2="table"/>
        <exclude body1="middle1" body2="table"/>
        <exclude body1="middle2" body2="table"/>
        <exclude body1="middle3" body2="table"/>
        <exclude body1="ring0" body2="table"/>
        <exclude body1="ring1" body2="table"/>
        <exclude body1="ring2" body2="table"/>
        <exclude body1="ring3" body2="table"/>
        <exclude body1="mocap" body2="object"/>
        <exclude body1="palm" body2="object"/>
        <exclude body1="thumb0" body2="object"/>
        <exclude body1="thumb1" body2="object"/>
        <exclude body1="thumb2" body2="object"/>
        <exclude body1="thumb3" body2="object"/>
        <exclude body1="little0" body2="object"/>
        <exclude body1="little1" body2="object"/>
        <exclude body1="little2" body2="object"/>
        <exclude body1="little3" body2="object"/>
        <exclude body1="fore0" body2="object"/>
        <exclude body1="fore1" body2="object"/>
        <exclude body1="fore2" body2="object"/>
        <exclude body1="fore3" body2="object"/>
        <exclude body1="middle0" body2="object"/>
        <exclude body1="middle1" body2="object"/>
        <exclude body1="middle2" body2="object"/>
        <exclude body1="middle3" body2="object"/>
        <exclude body1="ring0" body2="object"/>
        <exclude body1="ring1" body2="object"/>
        <exclude body1="ring2" body2="object"/>
        <exclude body1="ring3" body2="object"/>
        -->
        
    </contact>

    <worldbody>
        <camera name="fixed" pos="-1 0 0.7" zaxis="-1 0 1" fovy="60" ipd="0.068"/>

        <body name="mocap" mocap="true" pos="-0.005 0.175 2.02"> <!-- 0 0.173 10.025 -->
            <geom type="box" group="2" size="0.02 0.02 0.02" contype="0" conaffinity="0" rgba=".9 .5 .5 1"/>
        </body>
        
		<!-- ======= ROBOT ======= -->
        <body childclass="BHAM" name="forearm" pos="0 0 2" euler="0 3.141592 3.141592">
            <joint class="free"/>
            <geom type="cylinder" size="0.02 0.01"/>
            <body name="palm" pos="0 0 0">
            	<geom type="mesh" contype="0" conaffinity="0" mesh="righthandbase"/>
                <geom type="mesh" mass="0.000001" mesh="palm1" rgba="0 0 0 0"/>
                <geom type="mesh" mass="0.000001" mesh="palm2" rgba="0 0 0 0"/>
                <geom type="mesh" mass="0.000001" mesh="palm3" rgba="0 0 0 0"/>
                <geom type="mesh" mass="0.000001" mesh="palm4" rgba="0 0 0 0"/>
                <geom type="mesh" mass="0.000001" mesh="palm5" rgba="0 0 0 0"/>
                <geom type="mesh" mass="0.000001" mesh="palm6" rgba="0 0 0 0"/>
                <geom type="mesh" mass="0.000001" mesh="palm7" rgba="0 0 0 0"/>
                <geom type="mesh" mass="0.000001" mesh="palm8" rgba="0 0 0 0"/>
                <geom type="mesh" mass="0.000001" mesh="palm9" rgba="0 0 0 0"/>
                <geom type="mesh" mass="0.000001" mesh="palm10" rgba="0 0 0 0"/>
                <geom type="mesh" mass="0.000001" mesh="palm11" rgba="0 0 0 0"/>
                <geom type="mesh" mass="0.000001" mesh="palm12" rgba="0 0 0 0"/>
                <geom type="mesh" mass="0.000001" mesh="palm13" rgba="0 0 0 0"/>
                <geom type="mesh" mass="0.000001" mesh="palm14" rgba="0 0 0 0"/>
                <geom type="mesh" mass="0.000001" mesh="palm15" rgba="0 0 0 0"/>
                <geom type="mesh" mass="0.000001" mesh="palm16" rgba="0 0 0 0"/>
                <geom type="mesh" mass="0.000001" mesh="palm17" rgba="0 0 0 0"/>
                <geom type="mesh" mass="0.000001" mesh="palm18" rgba="0 0 0 0"/>
                <geom type="mesh" mass="0.000001" mesh="palm19" rgba="0 0 0 0"/>
                
                <!-- ======= THUMB  ======= -->
                <body name="thumb0">
               	<joint name="thumb_ABD" type="hinge" pos="0.0443196 0.0787516 0.0622977" axis="0.549586 -0.456218 0.699872" range="-0.26180 0.26180"/>
                	<geom type="mesh" mass="0.000001" mesh="thumb_basecover"/>
					<body name="thumb1">
						<joint name="thumb_IN" type="hinge" pos="0.036754 0.056714 0.04474" axis="-0.814200 -0.104803 0.571047" range="0.087266 1.5708" ref="0.087266"/>
                		<geom type="mesh" mass="0.000001" mesh="thumb_proximalp"/>
						<body name="thumb2">
							<joint name="thumb_OUT" type="hinge" pos="0.046615 0.10503 0.06708" axis="-0.814200 -0.104803 0.571047" range="0.087266 1.4835" ref="0.087266"/>
							<geom type="mesh" mass="0.000001" mesh="thumb_middlep"/>
							<body name="thumb3">
								<joint name="thumb_TIP" type="hinge" pos="0.050016 0.12692 0.078691" axis="-0.814200 -0.104803 0.571047" range="0.087266 1.4835" ref="0.087266"/>
								<geom type="mesh" mass="0.000001" mesh="thumb_distalp"/>
							</body>
						</body>
					</body>
				</body>
				
				<!-- ======= FORE  ======= -->
                <body name="fore0">
                	<joint name="fore_ABD" type="hinge" pos="0.0369151 0.107841 -0.00256829" axis="0.087156 0.000000 -0.996195" range="-0.26180 0.26180"/> 
					<geom type="mesh" mass="0.000001" mesh="fore_basecover"/>
					<body name="fore1">
						<joint name="fore_IN" type="hinge" pos="0.029434 0.08577 -0.020007" axis="0.996195 0.000000 0.087156" range="0.087266 1.5708" ref="0.087266"/>
                		<geom type="mesh" mass="0.000001" mesh="fore_proximalp"/>
						<body name="fore2">
							<joint name="fore_OUT" type="hinge" pos="0.029014 0.1399 -0.019052" axis="0.996195 0.000000 0.087156" range="0.087266 1.4835" ref="0.087266"/>
							<geom type="mesh" mass="0.000001" mesh="fore_middlep"/>
							<body name="fore3">
								<joint name="fore_TIP" type="hinge" pos="0.030576 0.16486 -0.018924" axis="0.996195 0.000000 0.087156" range="0.087266 1.4835" ref="0.087266"/>
								<geom type="mesh" mass="0.000001" mesh="fore_distalp"/>
							</body>
						</body>
					</body>
				</body>
				
				<!-- ======= MIDDLE  ======= -->
                <body name="middle0">
					<joint name="middle_ABD" type="hinge" pos="0.0101112 0.117841 -0.00374828" axis="0.000000 0.000000 -1.000000" range="-0.26180 0.26180"/>
					<geom type="mesh" mass="0.000001" mesh="middle_basecover"/>
					<body name="middle1">
						<joint name="middle_IN" type="hinge" pos="0.0026354 0.09577 -0.021189" axis="1.000000 0.000000 0.000000" range="0.087266 1.5708" ref="0.087266"/>
                		<geom type="mesh" mass="0.000001" mesh="middle_proximalp"/>
						<body name="middle2">
							<joint name="middle_OUT" type="hinge" pos="0.0023 0.1499 -0.020201" axis="1.000000 0.000000 0.000000" range="0.087266 1.4835" ref="0.087266"/>
							<geom type="mesh" mass="0.000001" mesh="middle_middlep"/>
							<body name="middle3">
								<joint name="middle_TIP" type="hinge" pos="0.003867 0.17486 -0.02021" axis="1.000000 0.000000 0.000000" range="0.087266 1.4835" ref="0.087266"/>
								<geom type="mesh" mass="0.000001" mesh="middle_distalp"/>
							</body>
						</body>
					</body>
				</body>
				
				<!-- ======= RING  ======= -->
                <body name="ring0">
					<joint name="ring_ABD" type="hinge" pos="-0.0166936 0.112641 -0.00258767" axis="-0.087156 0.000000 -0.996195" range="-0.26180 0.26180"/>
					<geom type="mesh" mass="0.000001" mesh="ring_basecover"/>
					<body name="ring1">
						<joint name="ring_IN" type="hinge" pos="-0.024164 0.09057 -0.020031" axis="0.996195 0.000000 -0.087156" range="0.087266 1.5708" ref="0.087266"/>
                		<geom type="mesh" mass="0.000001" mesh="ring_proximalp"/>
						<body name="ring2">
							<joint name="ring_OUT" type="hinge" pos="-0.024412 0.1447 -0.019017" axis="0.996195 0.000000 -0.087156" range="0.087266 1.4835" ref="0.087266"/>
							<geom type="mesh" mass="0.000001" mesh="ring_middlep"/>
							<body name="ring3">
								<joint name="ring_TIP" type="hinge" pos="-0.022852 0.16966 -0.019162" axis="0.996195 0.000000 -0.087156" range="0.087266 1.4835" ref="0.087266"/>
								<geom type="mesh" mass="0.000001" mesh="ring_distalp"/>
							</body>
						</body>
					</body>
				</body>
				
				<!-- ======= LITTLE  ======= -->
                <body name="little0">
					<joint name="little_ABD" type="hinge" pos="-0.050761 0.07157 -0.016541" axis="-0.173648 0.000000 -0.984808" range="-0.26180 0.26180"/>
					<geom type="mesh" mass="0.000001" mesh="little_basecover"/>
					<body name="little1">
						<joint name="little_IN" type="hinge" pos="-0.050761 0.07157 -0.016541" axis="0.98481 0.00000 -0.17365" range="0.087266 1.5708" ref="0.087266"/>
                		<geom type="mesh" mass="0.000001" mesh="little_proximalp"/>
						<body name="little2">
						<joint name="little_OUT" type="hinge" pos="-0.05092 0.1257 -0.015509" axis="0.98481 0.00000 -0.17365" range="0.087266 1.4835" ref="0.087266"/>
							<geom type="mesh" mass="0.000001" mesh="little_middlep"/>
							<body name="little3">
							<joint name="little_TIP" type="hinge" pos="-0.049378 0.15066 -0.01579" axis="0.98481 0.00000 -0.17365" range="0.087266 1.4835" ref="0.087266"/>
								<geom type="mesh" mass="0.000001" mesh="little_distalp"/>
							</body>
						</body>
					</body>
				</body>
        	</body>
        </body>
        
    </worldbody>
	
<!--
	<tendon>
		<fixed name="T_index32_cpl" range="0 1">
			<joint joint="index_DIP"  coef="0.00705"/>
			<joint joint="index_PIP"  coef="-0.00805"/>
		</fixed>
		<fixed name="T_index21_cpl" range="0 1">
			<joint joint="index_PIP"  coef="0.010"/>
			<joint joint="index_MCP"  coef="-0.010"/>
		</fixed>
		
		<fixed name="T_middle32_cpl">
			<joint joint="middle_DIP"  coef="0.00705"/>
			<joint joint="middle_PIP"  coef="-0.00805"/>
		</fixed>
		<fixed name="T_middle21_cpl">
			<joint joint="middle_PIP"  coef="0.010"/>
			<joint joint="middle_MCP"  coef="-0.010"/>
		</fixed>
		
		<fixed name="T_ring32_cpl">
			<joint joint="ring_DIP"  coef="0.00705"/>
			<joint joint="ring_PIP"  coef="-0.00805"/>
		</fixed>
		<fixed name="T_ring21_cpl">
			<joint joint="ring_PIP"  coef="0.010"/>
			<joint joint="ring_MCP"  coef="-0.010"/>
		</fixed>
		
		<fixed name="T_pinky32_cpl">
			<joint joint="pinky_DIP"  coef="0.00705"/>
			<joint joint="pinky_PIP"  coef="-0.00805"/>
		</fixed>
		<fixed name="T_pinky21_cpl">
			<joint joint="pinky_PIP"  coef="0.010"/>
			<joint joint="pinky_MCP"  coef="-0.010"/>
		</fixed>
		
	</tendon>
	-->
	
	<equality>
        <weld body1="mocap" body2="forearm" solref="0.01 1" solimp=".9 .9 0.01"/>
    </equality>
	
	<!--
	<actuator>
        <position name="A_thumb_ABD"  class="BHAM" joint="thumb_ABD"  ctrlrange="-0.26180 0.26180"/>
        <position name="A_thumb_IN"  class="BHAM" joint="thumb_IN"  ctrlrange="0.087266 1.5708"/>
        <position name="A_thumb_OUT"  class="BHAM" joint="thumb_OUT"  ctrlrange="0.087266 1.4835"/>
        <position name="A_thumb_TIP"  class="BHAM" joint="thumb_TIP"  ctrlrange="0.087266 1.4835"/>
        <position name="A_fore_ABD"  class="BHAM" joint="fore_ABD"  ctrlrange="-0.26180 0.26180"/>
        <position name="A_fore_IN"  class="BHAM" joint="fore_IN"  ctrlrange="0.087266 1.5708"/>
        <position name="A_fore_OUT"  class="BHAM" joint="fore_OUT"  ctrlrange="0.087266 1.4835"/>
        <position name="A_fore_TIP"  class="BHAM" joint="fore_TIP"  ctrlrange="0.087266 1.4835"/>
        <position name="A_middle_ABD"  class="BHAM" joint="middle_ABD"  ctrlrange="-0.26180 0.26180"/>
        <position name="A_middle_IN"  class="BHAM" joint="middle_IN"  ctrlrange="0.087266 1.5708"/>
        <position name="A_middle_OUT"  class="BHAM" joint="middle_OUT"  ctrlrange="0.087266 1.4835"/>
        <position name="A_middle_TIP"  class="BHAM" joint="middle_TIP"  ctrlrange="0.087266 1.4835"/>
        <position name="A_ring_ABD"  class="BHAM" joint="ring_ABD"  ctrlrange="-0.26180 0.26180"/>
        <position name="A_ring_IN"  class="BHAM" joint="ring_IN"  ctrlrange="0.087266 1.5708"/>
        <position name="A_ring_OUT"  class="BHAM" joint="ring_OUT"  ctrlrange="0.087266 1.4835"/>
        <position name="A_ring_TIP"  class="BHAM" joint="ring_TIP"  ctrlrange="0.087266 1.4835"/>
        <position name="A_little_ABD"  class="BHAM" joint="little_ABD"  ctrlrange="-0.26180 0.26180"/>
        <position name="A_little_IN"  class="BHAM" joint="little_IN"  ctrlrange="0.087266 1.5708"/>
        <position name="A_little_OUT"  class="BHAM" joint="little_OUT"  ctrlrange="0.087266 1.4835"/>
        <position name="A_little_TIP"  class="BHAM" joint="little_TIP"  ctrlrange="0.087266 1.4835"/>
	</actuator>
	-->
	
	<actuator>
        <position name="A_thumb_ABD"  class="BHAM" joint="thumb_ABD"  ctrlrange="-0.26180 0.26180"/>
        <position name="A_thumb_IN"  class="BHAM" joint="thumb_IN"  ctrlrange="0.15 1.5708"/>
        <position name="A_thumb_OUT"  class="BHAM" joint="thumb_OUT"  ctrlrange="0.1571 1.4835"/>
        <position name="A_thumb_TIP"  class="BHAM" joint="thumb_TIP"  ctrlrange="0.1571 1.4835"/>
        <position name="A_fore_ABD"  class="BHAM" joint="fore_ABD"  ctrlrange="-0.26180 0.26180"/>
        <position name="A_fore_IN"  class="BHAM" joint="fore_IN"  ctrlrange="0.22 1.5708"/>
        <position name="A_fore_OUT"  class="BHAM" joint="fore_OUT"  ctrlrange="0.1571 1.4835"/>
        <position name="A_fore_TIP"  class="BHAM" joint="fore_TIP"  ctrlrange="0.1571 1.4835"/>
        <position name="A_middle_ABD"  class="BHAM" joint="middle_ABD"  ctrlrange="-0.26180 0.26180"/>
        <position name="A_middle_IN"  class="BHAM" joint="middle_IN"  ctrlrange="0.24 1.5708"/>
        <position name="A_middle_OUT"  class="BHAM" joint="middle_OUT"  ctrlrange="0.1571 1.4835"/>
        <position name="A_middle_TIP"  class="BHAM" joint="middle_TIP"  ctrlrange="0.1571 1.4835"/>
        <position name="A_ring_ABD"  class="BHAM" joint="ring_ABD"  ctrlrange="-0.26180 0.26180"/>
        <position name="A_ring_IN"  class="BHAM" joint="ring_IN"  ctrlrange="0.24 1.5708"/>
        <position name="A_ring_OUT"  class="BHAM" joint="ring_OUT"  ctrlrange="0.1571 1.4835"/>
        <position name="A_ring_TIP"  class="BHAM" joint="ring_TIP"  ctrlrange="0.1571 1.4835"/>
        <position name="A_little_ABD"  class="BHAM" joint="little_ABD"  ctrlrange="-0.26180 0.26180"/>
        <position name="A_little_IN"  class="BHAM" joint="little_IN"  ctrlrange="0.2 1.5708"/>
        <position name="A_little_OUT"  class="BHAM" joint="little_OUT"  ctrlrange="0.1571 1.4835"/>
        <position name="A_little_TIP"  class="BHAM" joint="little_TIP"  ctrlrange="0.1571 1.4835"/>
	</actuator>
	
</mujoco>
